<?xml version="1.0" encoding="UTF-8"?>
<!-- Generated by org.testng.reporters.JUnitReportReporter -->
<testsuite hostname="MSI" failures="1" tests="4" name="Amazon.Frameworkdesign.tests.ErrorValidationsTest" time="80.612" errors="0" timestamp="2024-02-13T23:27:01 IST" skipped="1">
  <testcase classname="Amazon.Frameworkdesign.tests.ErrorValidationsTest" name="LoginErrorValidation" time="17.826">
    <skipped/>
  </testcase> <!-- LoginErrorValidation -->
  <system-out/>
  <testcase classname="Amazon.Frameworkdesign.tests.ErrorValidationsTest" name="LoginErrorValidation" time="17.895">
    <failure message="expected [Login Successfully] but found [Login Successfully1]" type="java.lang.AssertionError">
      <![CDATA[java.lang.AssertionError: expected [Login Successfully] but found [Login Successfully1]
at org.testng.Assert.fail(Assert.java:99)
at org.testng.Assert.failNotEquals(Assert.java:1037)
at org.testng.Assert.assertEqualsImpl(Assert.java:140)
at org.testng.Assert.assertEquals(Assert.java:122)
at org.testng.Assert.assertEquals(Assert.java:629)
at org.testng.Assert.assertEquals(Assert.java:639)
at Amazon.Frameworkdesign.tests.ErrorValidationsTest.LoginErrorValidation(ErrorValidationsTest.java:26)
at java.base/jdk.internal.reflect.NativeMethodAccessorImpl.invoke0(Native Method)
at java.base/jdk.internal.reflect.NativeMethodAccessorImpl.invoke(NativeMethodAccessorImpl.java:64)
at java.base/jdk.internal.reflect.DelegatingMethodAccessorImpl.invoke(DelegatingMethodAccessorImpl.java:43)
at java.base/java.lang.reflect.Method.invoke(Method.java:564)
at org.testng.internal.MethodInvocationHelper.invokeMethod(MethodInvocationHelper.java:133)
at org.testng.internal.TestInvoker.invokeMethod(TestInvoker.java:598)
at org.testng.internal.TestInvoker.retryFailed(TestInvoker.java:213)
at org.testng.internal.MethodRunner.runInSequence(MethodRunner.java:58)
at org.testng.internal.TestInvoker$MethodInvocationAgent.invoke(TestInvoker.java:824)
at org.testng.internal.TestInvoker.invokeTestMethods(TestInvoker.java:146)
at org.testng.internal.TestMethodWorker.invokeTestMethods(TestMethodWorker.java:146)
at org.testng.internal.TestMethodWorker.run(TestMethodWorker.java:128)
at java.base/java.util.ArrayList.forEach(ArrayList.java:1511)
at org.testng.TestRunner.privateRun(TestRunner.java:794)
at org.testng.TestRunner.run(TestRunner.java:596)
at org.testng.SuiteRunner.runTest(SuiteRunner.java:377)
at org.testng.SuiteRunner.access$000(SuiteRunner.java:28)
at org.testng.SuiteRunner$SuiteWorker.run(SuiteRunner.java:418)
at org.testng.internal.thread.ThreadUtil.lambda$execute$0(ThreadUtil.java:64)
at java.base/java.util.concurrent.FutureTask.run(FutureTask.java:264)
at java.base/java.util.concurrent.ThreadPoolExecutor.runWorker(ThreadPoolExecutor.java:1130)
at java.base/java.util.concurrent.ThreadPoolExecutor$Worker.run(ThreadPoolExecutor.java:630)
at java.base/java.lang.Thread.run(Thread.java:832)
]]>
    </failure>
  </testcase> <!-- LoginErrorValidation -->
  <system-out/>
  <testcase classname="Amazon.Frameworkdesign.tests.ErrorValidationsTest" name="ProductErrorValidation" time="30.470"/>
  <system-out/>
  <testcase classname="Amazon.Frameworkdesign.tests.ErrorValidationsTest" name="ProductErrorValidation" time="14.421"/>
  <system-out/>
</testsuite> <!-- Amazon.Frameworkdesign.tests.ErrorValidationsTest -->
